Workbook

Sheet El wt% to oxide wt%
A1: Changing from element wt% to oxide wt%
A3: Sample calculation below is shown for a labradorite
A4: Replace numbers in red with your analysis (element wt %) to convert to oxide wt %.
A5: Only include Si, Ti, Al, Mn, Mg, Ca, Na, K -- the other elements are not accurate enough to be meaningful.
A6: Oxide wt % values appear in blue; cut and copy them into the appropriate mineral normalization spread sheet.
A7: When you paste, use the Paste Special>Values option.
A8: Analysis | B8: analysis | C8: B | D8: C | I8: normlalized
B9: analysis | C9: elem | D9: oxide | E9: # cations | F9: # oxygen | G9: oxide | H9: oxide | I9: oxide
A10: oxide | B10: wt % | C10: at wt | D10: at wt | E10: in oxide | F10: in oxide | G10: wt % | I10: wt %
A11: Si | B11: 30.526 | C11: ='Periodic Table'!F4 -> 28.0855 | D11: ='Periodic Table'!B4 -> 60.0843 | E11: ='Periodic Table'!D4 -> 1 | F11: ='Periodic Table'!E4 -> 2 | G11: =B11*D11/(C11*E11) -> 65.305348 | H11: ='Periodic Table'!A4 -> SiO2 | I11: =G11*100/G$24 -> 63.903187
A12: Ti | C12: ='Periodic Table'!F5 -> 47.9 | D12: ='Periodic Table'!B5 -> 79.8988 | E12: ='Periodic Table'!D5 -> 1 | F12: ='Periodic Table'!E5 -> 2 | G12: =B12*D12/(C12*E12) -> 0 | H12: ='Periodic Table'!A5 -> TiO2 | I12: =G12*100/G$24 -> 0
A13: Al | B13: 1.763 | C13: ='Periodic Table'!F6 -> 26.98154 | D13: ='Periodic Table'!B6 -> 101.96128 | E13: ='Periodic Table'!D6 -> 2 | F13: ='Periodic Table'!E6 -> 3 | G13: =B13*D13/(C13*E13) -> 3.3311245 | H13: ='Periodic Table'!A6 -> Al2O3 | I13: =G13*100/G$24 -> 3.2596024
A16: Fe | B16: 9.181 | C16: ='Periodic Table'!F9 -> 55.847 | D16: ='Periodic Table'!B9 -> 71.8464 | E16: ='Periodic Table'!D9 -> 1 | F16: ='Periodic Table'!E9 -> 1 | G16: =B16*D16/(C16*E16) -> 11.811231 | H16: ='Periodic Table'!A9 -> FeO | I16: =G16*100/G$24 -> 11.557634
A17: Mn | C17: ='Periodic Table'!F10 -> 54.938 | D17: ='Periodic Table'!B10 -> 70.9374 | E17: ='Periodic Table'!D10 -> 1 | F17: ='Periodic Table'!E10 -> 1 | G17: =B17*D17/(C17*E17) -> 0 | H17: ='Periodic Table'!A10 -> MnO
A18: Mg | B18: 12.325 | C18: ='Periodic Table'!F11 -> 24.305 | D18: ='Periodic Table'!B11 -> 40.3044 | E18: ='Periodic Table'!D11 -> 1 | F18: ='Periodic Table'!E11 -> 1 | G18: =B18*D18/(C18*E18) -> 20.438253 | H18: ='Periodic Table'!A11 -> MgO | I18: =G18*100/G$24 -> 19.999426
A19: Ca | B19: 0.935 | C19: ='Periodic Table'!F12 -> 40.08 | D19: ='Periodic Table'!B12 -> 56.0794 | E19: ='Periodic Table'!D12 -> 1 | F19: ='Periodic Table'!E12 -> 1 | G19: =B19*D19/(C19*E19) -> 1.3082395 | H19: ='Periodic Table'!A12 -> CaO | I19: =G19*100/G$24 -> 1.2801505
A21: Na | C21: ='Periodic Table'!F14 -> 22.98977 | D21: ='Periodic Table'!B14 -> 61.97894 | E21: ='Periodic Table'!D14 -> 2 | F21: ='Periodic Table'!E14 -> 1 | G21: =B21*D21/(C21*E21) -> 0 | H21: ='Periodic Table'!A14 -> Na2O | I21: =G21*100/G$24 -> 0
A22: K | C22: ='Periodic Table'!F15 -> 39.0983 | D22: ='Periodic Table'!B15 -> 94.196 | E22: ='Periodic Table'!D15 -> 2 | F22: ='Periodic Table'!E15 -> 1 | G22: =B22*D22/(C22*E22) -> 0 | H22: ='Periodic Table'!A15 -> K2O | I22: =G22*100/G$24 -> 0
A24: total | B24: =SUM(B11:B22) -> 54.73 | G24: =SUM(G11:G22) -> 102.19419 | I24: =SUM(I11:I22) -> 100
A25: ideal | G25: 100

Sheet Plagioclase
A1: Recalculation of a feldspar anlaysis (all Fe as FeO) and solving for Fe+3
A3: Sample calculation below is shown for a labradorite
A4: Replace numbers in red with your analysis to normalize your sample.
A5: Do not include a value for Fe2O3 (in blue) unless it was determined by analysis.
A6: If you omit a value for Fe2O3, it will be calculated, if possible, from charge balance.
A8: Analysis
B9: analysis | C9: mole | D9: mole | E9: norm. | F9: norm. | G9: atom | H9: norm
A10: oxide | B10: wt % | C10: cations | D10: oxygen | E10: cations | F10: oxygen | G10: units | H10: oxygen
A11: ='Periodic Table'!A4 -> SiO2 | B11: 53.66 | C11: ='Periodic Table'!D4*B11/'Periodic Table'!B4 -> 0.89307856 | D11: ='Periodic Table'!E4*B11/'Periodic Table'!B4 -> 1.7861571 | E11: =IF(B$15>0,H$25*C11/D$24,G$25*C11/C$24) -> 2.428501 | F11: =E11*'Periodic Table'!E4/'Periodic Table'!D4 -> 4.8570021 | G11: =E11 -> 2.428501 | H11: =F11 -> 4.8570021
A12: ='Periodic Table'!A5 -> TiO2 | B12: 0 | C12: ='Periodic Table'!D5*B12/'Periodic Table'!B5 -> 0 | D12: ='Periodic Table'!E5*B12/'Periodic Table'!B5 -> 0 | E12: =IF(B$15>0,H$25*C12/D$24,G$25*C12/C$24) -> 0 | F12: =E12*'Periodic Table'!E5/'Periodic Table'!D5 -> 0 | G12: =E12 -> 0 | H12: =F12 -> 0
A13: ='Periodic Table'!A6 -> Al2O3 | B13: 27.91 | C13: ='Periodic Table'!D6*B13/'Periodic Table'!B6 -> 0.54746272 | D13: ='Periodic Table'!E6*B13/'Periodic Table'!B6 -> 0.82119408 | E13: =IF(B$15>0,H$25*C13/D$24,G$25*C13/C$24) -> 1.4886863 | F13: =E13*'Periodic Table'!E6/'Periodic Table'!D6 -> 2.2330294 | G13: =E13 -> 1.4886863 | H13: =F13 -> 2.2330294
A14: ='Periodic Table'!A8 -> Cr2O3 | B14: 0 | C14: ='Periodic Table'!D8*B14/'Periodic Table'!B8 -> 0 | D14: ='Periodic Table'!E8*B14/'Periodic Table'!B8 -> 0 | E14: =IF(B$15>0,H$25*C14/D$24,G$25*C14/C$24) -> 0 | F14: =E14*'Periodic Table'!E8/'Periodic Table'!D8 -> 0 | G14: =E14 -> 0 | H14: =F14 -> 0
A15: ='Periodic Table'!A7 -> Fe2O3 | B15: 0 | C15: =IF(B15>0,'Periodic Table'!D7*B15/'Periodic Table'!B7,0) -> 0 | D15: =IF(B15>0,'Periodic Table'!E7*B15/'Periodic Table'!B7,0) -> 0 | E15: =IF(B$15>0,H$25*C15/D$24,G$25*C15/C$24) -> 0 | F15: =E15*'Periodic Table'!E7/'Periodic Table'!D7 -> 0 | G15: =IF(B15>0,E15,IF(F24<8,IF(2*(8-F24)>E16,E16,8-F24),0)) -> 0.028007564 | H15: ='Periodic Table'!E7*G15/'Periodic Table'!D7 -> 0.042011346
A16: ='Periodic Table'!A9 -> FeO | B16: 0.74 | C16: ='Periodic Table'!D9*B16/'Periodic Table'!B9 -> 0.010299751 | D16: ='Periodic Table'!E9*B16/'Periodic Table'!B9 -> 0.010299751 | E16: =IF(B$15>0,H$25*C16/D$24,G$25*C16/C$24) -> 0.028007564 | F16: =E16*'Periodic Table'!E9/'Periodic Table'!D9 -> 0.028007564 | G16: =IF(B15>0,E16,E16-G15) -> 0 | H16: ='Periodic Table'!E9*G16/'Periodic Table'!D9 -> 0
A17: ='Periodic Table'!A10 -> MnO | B17: 0 | C17: ='Periodic Table'!D10*B17/'Periodic Table'!B10 -> 0 | D17: ='Periodic Table'!E10*B17/'Periodic Table'!B10 -> 0 | E17: =IF(B$15>0,H$25*C17/D$24,G$25*C17/C$24) -> 0 | F17: =E17*'Periodic Table'!E10/'Periodic Table'!D10 -> 0 | G17: =IF(B16>0,E17,E17-G16) -> 0 | H17: =F17 -> 0
A18: ='Periodic Table'!A11 -> MgO | B18: 0.64 | C18: ='Periodic Table'!D11*B18/'Periodic Table'!B11 -> 0.01587916 | D18: ='Periodic Table'!E11*B18/'Periodic Table'!B11 -> 0.01587916 | E18: =IF(B$15>0,H$25*C18/D$24,G$25*C18/C$24) -> 0.043179354 | F18: =E18*'Periodic Table'!E11/'Periodic Table'!D11 -> 0.043179354 | G18: =IF(B17>0,E18,E18-G17) -> 0.043179354 | H18: =F18 -> 0.043179354
A19: ='Periodic Table'!A12 -> CaO | B19: 12.13 | C19: ='Periodic Table'!D12*B19/'Periodic Table'!B12 -> 0.21630046 | D19: ='Periodic Table'!E12*B19/'Periodic Table'!B12 -> 0.21630046 | E19: =IF(B$15>0,H$25*C19/D$24,G$25*C19/C$24) -> 0.58817434 | F19: =E19*'Periodic Table'!E12/'Periodic Table'!D12 -> 0.58817434 | G19: =IF(B18>0,E19,E19-G18) -> 0.58817434 | H19: =F19 -> 0.58817434
A20: ='Periodic Table'!A13 -> BaO | B20: 0 | C20: ='Periodic Table'!D13*B20/'Periodic Table'!B13 -> 0 | D20: ='Periodic Table'!E13*B20/'Periodic Table'!B13 -> 0 | E20: =IF(B$15>0,H$25*C20/D$24,G$25*C20/C$24) -> 0 | F20: =E20*'Periodic Table'!E13/'Periodic Table'!D13 -> 0 | G20: =IF(B19>0,E20,E20-G19) -> 0 | H20: =F20 -> 0
A21: ='Periodic Table'!A14 -> Na2O | B21: 4.76 | C21: ='Periodic Table'!D14*B21/'Periodic Table'!B14 -> 0.15360056 | D21: ='Periodic Table'!E14*B21/'Periodic Table'!B14 -> 0.076800281 | E21: =IF(B$15>0,H$25*C21/D$24,G$25*C21/C$24) -> 0.41767784 | F21: =E21*'Periodic Table'!E14/'Periodic Table'!D14 -> 0.20883892 | G21: =IF(B20>0,E21,E21-G20) -> 0.41767784 | H21: =F21 -> 0.20883892
A22: ='Periodic Table'!A15 -> K2O | B22: 0.1 | C22: ='Periodic Table'!D15*B22/'Periodic Table'!B15 -> 0.0021232324 | D22: ='Periodic Table'!E15*B22/'Periodic Table'!B15 -> 0.0010616162 | E22: =IF(B$15>0,H$25*C22/D$24,G$25*C22/C$24) -> 0.005773593 | F22: =E22*'Periodic Table'!E15/'Periodic Table'!D15 -> 0.0028867965 | G22: =IF(B21>0,E22,E22-G21) -> 0.005773593 | H22: =F22 -> 0.0028867965
A24: total | B24: =SUM(B11:B22) -> 99.94 | C24: =SUM(C11:C22) -> 1.8387444 | D24: =SUM(D11:D22) -> 2.9276925 | E24: =SUM(E11:E22) -> 5 | F24: =SUM(F11:F22) -> 7.9611185 | G24: =SUM(G11:G22) -> 5 | H24: =SUM(H11:H22) -> 7.9751222
A25: ideal | G25: 5 | H25: 8
E26: =IF(G27<15.95,"Note: insufficient cation charge",IF(G27>16.05,"Note: too much cation charge"," "))
A27: calculated charge | C27: =4*(C11+C12)+3*(C13+C15+C14)+2*(C16+C17+C18+C19+C20)+C21+C22 -> 5.8553849 | D27: =2*SUM(D11:D22)*(-1) -> -5.8553849 | E27: =4*(E11+E12)+3*(E13+E15+E14)+2*(E16+E17+E18+E19+E20)+E21+E22 -> 15.922237 | F27: =2*SUM(F11:F22)*(-1) -> -15.922237 | G27: =4*(G11+G12)+3*(G13+G15+G14)+2*(G16+G17+G18+G19+G20)+G21+G22 -> 15.950244 | H27: =2*SUM(H11:H22)*(-1) -> -15.950244
A29: Results of normalization are given in the box, below. If some Fe was calculated to
A30: be Fe3+, the total for the analysis will inrease.
A32: Normalized Analysis
G33: end | H33: mole
A34: oxide | B34: wt % | D34: cations | E34: atoms | G34: member | H34: %
A35: ='Periodic Table'!A4 -> SiO2 | B35: =B11 -> 53.66 | D35: ='Periodic Table'!C4 -> Si | E35: =G11 -> 2.428501 | G35: An | H35: =E43/(E43+E45+E46)*100 -> 58.141494
A36: ='Periodic Table'!A5 -> TiO2 | B36: =B12 -> 0 | D36: ='Periodic Table'!C5 -> Ti | E36: =G12 -> 0 | G36: Ab | H36: =E45/(E43+E45+E46)*100 -> 41.287782
A37: ='Periodic Table'!A6 -> Al2O3 | B37: =B13 -> 27.91 | D37: ='Periodic Table'!C6 -> Al | E37: =G13 -> 1.4886863 | G37: Or | H37: =E46/(E43+E45+E46)*100 -> 0.57072419
A38: ='Periodic Table'!A8 -> Cr2O3 | B38: =B14 -> 0 | D38: ='Periodic Table'!C8 -> Cr | E38: =G14 -> 0
A39: ='Periodic Table'!A7 -> Fe2O3 | B39: =IF(B15>0,B15,('Periodic Table'!B8/(2*'Periodic Table'!B10))*B16*G15/(G15+G16)) -> 0.79276057 | D39: ='Periodic Table'!C7 -> Fe3 | E39: =G15 -> 0.028007564 | G39: *based on Ca,
A40: ='Periodic Table'!A9 -> FeO | B40: =IF(B15>0,B16,B16*G16/(G16+G15)) -> 0 | D40: ='Periodic Table'!C9 -> Fe2 | E40: =G16 -> 0 | G40: Na, K ratios only
A41: ='Periodic Table'!A10 -> MnO | B41: =B17 -> 0 | D41: ='Periodic Table'!C10 -> Mn | E41: =G17 -> 0
A42: ='Periodic Table'!A11 -> MgO | B42: =B18 -> 0.64 | D42: ='Periodic Table'!C11 -> Mg | E42: =G18 -> 0.043179354 | G42: Si+Ti+Al+Fe3= | H42: =E35+E37+E39 -> 3.9451949
A43: ='Periodic Table'!A12 -> CaO | B43: =B19 -> 12.13 | D43: ='Periodic Table'!C12 -> Ca | E43: =G19 -> 0.58817434 | G43: ideal = | H43: 4
A44: ='Periodic Table'!A13 -> BaO | B44: =B20 -> 0 | D44: ='Periodic Table'!C13 -> Ba | E44: =G20 -> 0
A45: ='Periodic Table'!A14 -> Na2O | B45: =B21 -> 4.76 | D45: ='Periodic Table'!C14 -> Na | E45: =G21 -> 0.41767784 | G45: Ca+Na+K= | H45: =E43+E45+E46 -> 1.0116258
...

Sheet Pyroxene
A1: Recalculation of a pyroxene anlaysis (all Fe as FeO) and solving for Fe+3
A3: Sample calculation below is shown for a clinopyroxene from a lherzolite.
A4: Replace numbers in red with your analysis to normalize your sample.
A5: Do not include a value for Fe2O3 unless it was determined by analysis.
A6: If you omit a value for Fe2O3, it will be calculated, if possible, from charge balance.
A8: Analysis
B9: analysis | C9: mole | D9: mole | E9: norm. | F9: norm. | G9: atom | H9: norm
A10: oxide | B10: wt % | C10: cations | D10: oxygen | E10: cations | F10: oxygen | G10: units | H10: oxygen
A11: ='Periodic Table'!A4 -> SiO2 | B11: 63.338416 | C11: ='Periodic Table'!D4*B11/'Periodic Table'!B4 -> 1.0541592 | D11: ='Periodic Table'!E4*B11/'Periodic Table'!B4 -> 2.1083183 | E11: =IF(B$15>0,H$23*C11/D$22,G$23*C11/C$22) -> 2.3377353 | F11: =E11*'Periodic Table'!E4/'Periodic Table'!D4 -> 4.6754706 | G11: =E11 -> 2.3377353 | H11: =F11 -> 4.6754706
A12: ='Periodic Table'!A5 -> TiO2 | B12: 0 | C12: ='Periodic Table'!D5*B12/'Periodic Table'!B5 -> 0 | D12: ='Periodic Table'!E5*B12/'Periodic Table'!B5 -> 0 | E12: =IF(B$15>0,H$23*C12/D$22,G$23*C12/C$22) -> 0 | F12: =E12*'Periodic Table'!E5/'Periodic Table'!D5 -> 0 | G12: =E12 -> 0 | H12: =F12 -> 0
A13: ='Periodic Table'!A6 -> Al2O3 | B13: 3.2307943 | C13: ='Periodic Table'!D6*B13/'Periodic Table'!B6 -> 0.063372966 | D13: ='Periodic Table'!E6*B13/'Periodic Table'!B6 -> 0.095059448 | E13: =IF(B$15>0,H$23*C13/D$22,G$23*C13/C$22) -> 0.14053781 | F13: =E13*'Periodic Table'!E6/'Periodic Table'!D6 -> 0.21080671 | G13: =E13 -> 0.14053781 | H13: =F13 -> 0.21080671
A14: ='Periodic Table'!A8 -> Cr2O3 | C14: ='Periodic Table'!D8*B14/'Periodic Table'!B8 -> 0 | D14: ='Periodic Table'!E8*B14/'Periodic Table'!B8 -> 0 | E14: =IF(B$15>0,H$23*C14/D$22,G$23*C14/C$22) -> 0 | F14: =E14*'Periodic Table'!E8/'Periodic Table'!D8 -> 0 | G14: =E14 -> 0 | H14: =F14 -> 0
A15: ='Periodic Table'!A7 -> Fe2O3 | C15: =IF(B15>0,'Periodic Table'!D7*B15/'Periodic Table'!B7,0) -> 0 | D15: =IF(B15>0,'Periodic Table'!E7*B15/'Periodic Table'!B7,0) -> 0 | E15: =IF(B$15>0,H$23*C15/D$22,G$23*C15/C$22) -> 0 | F15: =E15*'Periodic Table'!E7/'Periodic Table'!D7 -> 0 | G15: =IF(B15>0,E15,IF((2*H23)-E25>0,(2*H23)-E25,0)) -> 0 | H15: ='Periodic Table'!E7*G15/'Periodic Table'!D7 -> 0
A16: ='Periodic Table'!A9 -> FeO | B16: 12.33928 | C16: ='Periodic Table'!D9*B16/'Periodic Table'!B9 -> 0.17174528 | D16: ='Periodic Table'!E9*B16/'Periodic Table'!B9 -> 0.17174528 | E16: =IF(B$15>0,H$23*C16/D$22,G$23*C16/C$22) -> 0.38086753 | F16: =E16*'Periodic Table'!E9/'Periodic Table'!D9 -> 0.38086753 | G16: =IF(B15>0,E16,E16-G15) -> 0.38086753 | H16: ='Periodic Table'!E9*G16/'Periodic Table'!D9 -> 0.38086753
A17: ='Periodic Table'!A10 -> MnO | C17: ='Periodic Table'!D10*B17/'Periodic Table'!B10 -> 0 | D17: ='Periodic Table'!E10*B17/'Periodic Table'!B10 -> 0 | E17: =IF(B$15>0,H$23*C17/D$22,G$23*C17/C$22) -> 0 | F17: =E17*'Periodic Table'!E10/'Periodic Table'!D10 -> 0 | G17: =E17 -> 0 | H17: =F17 -> 0
A18: ='Periodic Table'!A11 -> MgO | B18: 19.822673 | C18: ='Periodic Table'!D11*B18/'Periodic Table'!B11 -> 0.49182404 | D18: ='Periodic Table'!E11*B18/'Periodic Table'!B11 -> 0.49182404 | E18: =IF(B$15>0,H$23*C18/D$22,G$23*C18/C$22) -> 1.0906839 | F18: =E18*'Periodic Table'!E11/'Periodic Table'!D11 -> 1.0906839 | G18: =E18 -> 1.0906839 | H18: =F18 -> 1.0906839
A19: ='Periodic Table'!A12 -> CaO | B19: 1.2688366 | C19: ='Periodic Table'!D12*B19/'Periodic Table'!B12 -> 0.022625717 | D19: ='Periodic Table'!E12*B19/'Periodic Table'!B12 -> 0.022625717 | E19: =IF(B$15>0,H$23*C19/D$22,G$23*C19/C$22) -> 0.050175475 | F19: =E19*'Periodic Table'!E12/'Periodic Table'!D12 -> 0.050175475 | G19: =E19 -> 0.050175475 | H19: =F19 -> 0.050175475
A20: ='Periodic Table'!A14 -> Na2O | C20: ='Periodic Table'!D14*B20/'Periodic Table'!B14 -> 0 | D20: ='Periodic Table'!E14*B20/'Periodic Table'!B14 -> 0 | E20: =IF(B$15>0,H$23*C20/D$22,G$23*C20/C$22) -> 0 | F20: =E20*'Periodic Table'!E14/'Periodic Table'!D14 -> 0 | G20: =E20 -> 0 | H20: =F20 -> 0
B21: 0
A22: total | B22: 0 | C22: =SUM(C11:C20) -> 1.8037272 | D22: =SUM(D11:D20) -> 2.8895728 | E22: =SUM(E11:E20) -> 4 | F22: =SUM(F11:F20) -> 6.4080042 | G22: =SUM(G11:G20) -> 4 | H22: =SUM(H11:H20) -> 6.4080042
A23: ideal | G23: 4 | H23: 6
E24: =IF(G25<11.95,"Note: insufficient cation charge",IF(G25>12.05,"Note: too much cation charge"," ")) -> Note: too much cation charge
A25: calculated charge | C25: =4*(C11+C12)+3*(C13+C15+C14)+2*(C16+C17+C18+C19)+C20 -> 5.7791457 | D25: =2*SUM(D11:D20)*(-1) -> -5.7791457 | E25: =4*(E11+E12)+3*(E13+E15+E14)+2*(E16+E17+E18+E19)+E20 -> 12.816008 | F25: =2*SUM(F11:F20)*(-1) -> -12.816008 | G25: =4*(G11+G12)+3*(G13+G15+G14)+2*(G16+G17+G18+G19)+G20 -> 12.816008 | H25: =2*SUM(H11:H20)*(-1) -> -12.816008
A27: Results of normalization are given in the box, below. If some Fe was calculated to
A28: be Fe3+, the total for the analysis will inrease.
A29: End member %s are based on Ca, Mg, Fe-total ratios only.
A31: Normalized Analysis
A33: oxide | B33: wt % | D33: cations | E33: atoms
A34: ='Periodic Table'!A4 -> SiO2 | B34: =B11 -> 63.338416 | D34: ='Periodic Table'!C4 -> Si | E34: =G11 -> 2.3377353
A35: ='Periodic Table'!A5 -> TiO2 | B35: =B12 -> 0 | D35: ='Periodic Table'!C5 -> Ti | E35: =G12 -> 0
A36: ='Periodic Table'!A6 -> Al2O3 | B36: =B13 -> 3.2307943 | D36: ='Periodic Table'!C6 -> Al | E36: =G13 -> 0.14053781
A37: ='Periodic Table'!A8 -> Cr2O3 | B37: =B14 -> 0 | D37: ='Periodic Table'!C8 -> Cr | E37: =G14 -> 0
A38: ='Periodic Table'!A7 -> Fe2O3 | B38: =IF(B15>0,B15,('Periodic Table'!B7/(2*'Periodic Table'!B9))*B16*G15/(G15+G16)) -> 0 | D38: ='Periodic Table'!C7 -> Fe3 | E38: =G15 -> 0
A39: ='Periodic Table'!A9 -> FeO | B39: =IF(B15>0,B16,B16*G16/(G16+G15)) -> 12.33928 | D39: ='Periodic Table'!C9 -> Fe2 | E39: =G16 -> 0.38086753
A40: ='Periodic Table'!A10 -> MnO | B40: =B17 -> 0 | D40: ='Periodic Table'!C10 -> Mn | E40: =G17 -> 0
A41: ='Periodic Table'!A11 -> MgO | B41: =B18 -> 19.822673 | D41: ='Periodic Table'!C11 -> Mg | E41: =G18 -> 1.0906839
A42: ='Periodic Table'!A12 -> CaO | B42: =B19 -> 1.2688366 | D42: ='Periodic Table'!C12 -> Ca | E42: =G19 -> 0.050175475
A43: ='Periodic Table'!A14 -> Na2O | B43: =B20 -> 0 | D43: ='Periodic Table'!C14 -> Na | E43: =G20 -> 0
D44: tot. cat. | E44: =G22 -> 4
A45: total | B45: =SUM(B34:B43) -> 100 | D45: tot. oxy. | E45: =H22 -> 6.4080042
...

Sheet Garnet
A1: Recalculation of a garnet anlaysis (all Fe as FeO) and solving for Fe+3
A3: Sample calculation below is shown for a garnet from an Napak, Uganda
A4: Replace numbers in red with your analysis to normalize your sample.
A5: Do not include a value for Fe2O3 (in blue) unless it was determined by analysis.
A6: If you omit a value for Fe2O3, it will be calculated, if possible, from charge balance.
A8: Analysis
B9: analysis | C9: mole | D9: mole | E9: norm. | F9: norm. | G9: atom | H9: norm
A10: oxide | B10: wt % | C10: cations | D10: oxygen | E10: cations | F10: oxygen | G10: units | H10: oxygen
A11: ='Periodic Table'!A4 -> SiO2 | B11: 37.39 | C11: ='Periodic Table'!D4*B11/'Periodic Table'!B4 -> 0.62229235 | D11: ='Periodic Table'!E4*B11/'Periodic Table'!B4 -> 1.2445847 | E11: =IF(B$15>0,H$22*C11/D$21,G$22*C11/C$21) -> 2.9960531 | F11: =E11*'Periodic Table'!E4/'Periodic Table'!D4 -> 5.9921061 | G11: =E11 -> 2.9960531 | H11: =F11 -> 5.9921061
A12: ='Periodic Table'!A5 -> TiO2 | B12: 0.28 | C12: ='Periodic Table'!D5*B12/'Periodic Table'!B5 -> 0.0035044331 | D12: ='Periodic Table'!E5*B12/'Periodic Table'!B5 -> 0.0070088662 | E12: =IF(B$15>0,H$22*C12/D$21,G$22*C12/C$21) -> 0.016872243 | F12: =E12*'Periodic Table'!E5/'Periodic Table'!D5 -> 0.033744486 | G12: =E12 -> 0.016872243 | H12: =F12 -> 0.033744486
A13: ='Periodic Table'!A6 -> Al2O3 | B13: 10.08 | C13: ='Periodic Table'!D6*B13/'Periodic Table'!B6 -> 0.19772212 | D13: ='Periodic Table'!E6*B13/'Periodic Table'!B6 -> 0.29658317 | E13: =IF(B$15>0,H$22*C13/D$21,G$22*C13/C$21) -> 0.95194157 | F13: =E13*'Periodic Table'!E6/'Periodic Table'!D6 -> 1.4279124 | G13: =E13 -> 0.95194157 | H13: =F13 -> 1.4279124
A14: ='Periodic Table'!A8 -> Cr2O3 | B14: 0 | C14: ='Periodic Table'!D8*B14/'Periodic Table'!B8 -> 0 | D14: ='Periodic Table'!E8*B14/'Periodic Table'!B8 -> 0 | E14: =IF(B$15>0,H$22*C14/D$21,G$22*C14/C$21) -> 0 | F14: =E14*'Periodic Table'!E8/'Periodic Table'!D8 -> 0 | G14: =E14 -> 0 | H14: =F14 -> 0
A15: ='Periodic Table'!A7 -> Fe2O3 | B15: 0 | C15: =IF(B15>0,'Periodic Table'!D7*B15/'Periodic Table'!B7,0) -> 0 | D15: =IF(B15>0,'Periodic Table'!E7*B15/'Periodic Table'!B7,0) -> 0 | E15: =IF(B$15>0,H$22*C15/D$21,G$22*C15/C$21) -> 0 | F15: =E15*'Periodic Table'!E7/'Periodic Table'!D7 -> 0 | G15: =IF(B15>0,E15,IF((2*H22)-E24>0,(2*H22)-E24,0)) -> 1.0222078 | H15: ='Periodic Table'!E7*G15/'Periodic Table'!D7 -> 1.5333117
A16: ='Periodic Table'!A9 -> FeO | B16: 19.35 | C16: ='Periodic Table'!D9*B16/'Periodic Table'!B9 -> 0.26932456 | D16: ='Periodic Table'!E9*B16/'Periodic Table'!B9 -> 0.26932456 | E16: =IF(B$15>0,H$22*C16/D$21,G$22*C16/C$21) -> 1.2966746 | F16: =E16*'Periodic Table'!E9/'Periodic Table'!D9 -> 1.2966746 | G16: =IF(B15>0,E16,E16-G15) -> 0.27446678 | H16: ='Periodic Table'!E9*G16/'Periodic Table'!D9 -> 0.27446678
A17: ='Periodic Table'!A10 -> MnO | B17: 0.14 | C17: ='Periodic Table'!D10*B17/'Periodic Table'!B10 -> 0.0019735711 | D17: ='Periodic Table'!E10*B17/'Periodic Table'!B10 -> 0.0019735711 | E17: =IF(B$15>0,H$22*C17/D$21,G$22*C17/C$21) -> 0.0095018422 | F17: =E17*'Periodic Table'!E10/'Periodic Table'!D10 -> 0.0095018422 | G17: =E17 -> 0.0095018422 | H17: =F17 -> 0.0095018422
A18: ='Periodic Table'!A11 -> MgO | B18: 1.55 | C18: ='Periodic Table'!D11*B18/'Periodic Table'!B11 -> 0.03845734 | D18: ='Periodic Table'!E11*B18/'Periodic Table'!B11 -> 0.03845734 | E18: =IF(B$15>0,H$22*C18/D$21,G$22*C18/C$21) -> 0.1851545 | F18: =E18*'Periodic Table'!E11/'Periodic Table'!D11 -> 0.1851545 | G18: =E18 -> 0.1851545 | H18: =F18 -> 0.1851545
A19: ='Periodic Table'!A12 -> CaO | B19: 29.63 | C19: ='Periodic Table'!D12*B19/'Periodic Table'!B12 -> 0.52835801 | D19: ='Periodic Table'!E12*B19/'Periodic Table'!B12 -> 0.52835801 | E19: =IF(B$15>0,H$22*C19/D$21,G$22*C19/C$21) -> 2.5438022 | F19: =E19*'Periodic Table'!E12/'Periodic Table'!D12 -> 2.5438022 | G19: =E19 -> 2.5438022 | H19: =F19 -> 2.5438022
A21: total | B21: =SUM(B11:B19) -> 98.42 | C21: =SUM(C11:C19) -> 1.6616324 | D21: =SUM(D11:D19) -> 2.3862902 | E21: =SUM(E11:E19) -> 8 | F21: =SUM(F11:F19) -> 11.488896 | G21: =SUM(G11:G19) -> 8 | H21: =SUM(H11:H19) -> 12
A22: ideal | G22: 8 | H22: 12
E23: =IF(G24<23.95,"Note: insufficient cation charge",IF(G24>24.05,"Note: too much cation charge"," "))
A24: calculated charge | C24: =4*(C11+C12)+3*(C13+C15+C14)+2*(C16+C17+C18+C19) -> 4.7725804 | D24: =2*SUM(D11:D19)*(-1) -> -4.7725804 | E24: =4*(E11+E12)+3*(E13+E15+E14)+2*(E16+E17+E18+E19) -> 22.977792 | F24: =2*SUM(F11:F19)*(-1) -> -22.977792 | G24: =4*(G11+G12)+3*(G13+G15+G14)+2*(G16+G17+G18+G19) -> 24 | H24: =2*SUM(H11:H19)*(-1) -> -24
A26: Results of normalization are given in the box, below. If some Fe was calculated to
A27: be Fe3+, the total for the analysis will inrease.
A29: Normalized Analysis
A31: oxide | B31: wt % | D31: cations | E31: atoms
A32: ='Periodic Table'!A4 -> SiO2 | B32: =B11 -> 37.39 | D32: ='Periodic Table'!C4 -> Si | E32: =G11 -> 2.9960531
A33: ='Periodic Table'!A5 -> TiO2 | B33: =B12 -> 0.28 | D33: ='Periodic Table'!C5 -> Ti | E33: =G12 -> 0.016872243
A34: ='Periodic Table'!A6 -> Al2O3 | B34: =B13 -> 10.08 | D34: ='Periodic Table'!C6 -> Al | E34: =G13 -> 0.95194157
A35: ='Periodic Table'!A8 -> Cr2O3 | B35: =B14 -> 0 | D35: ='Periodic Table'!C8 -> Cr | E35: =G14 -> 0
A36: ='Periodic Table'!A7 -> Fe2O3 | B36: =IF(B15>0,G15,('Periodic Table'!B7/(2*'Periodic Table'!B9))*B16*G15/(G15+G16)) -> 16.95266 | D36: ='Periodic Table'!C7 -> Fe3 | E36: =G15 -> 1.0222078
A37: ='Periodic Table'!A9 -> FeO | B37: =IF(B15>0,B16,B16*G16/(G16+G15)) -> 4.0958096 | D37: ='Periodic Table'!C9 -> Fe2 | E37: =G16 -> 0.27446678
A38: ='Periodic Table'!A10 -> MnO | B38: =B17 -> 0.14 | D38: ='Periodic Table'!C10 -> Mn | E38: =G17 -> 0.0095018422
A39: ='Periodic Table'!A11 -> MgO | B39: =B18 -> 1.55 | D39: ='Periodic Table'!C11 -> Mg | E39: =G18 -> 0.1851545
A40: ='Periodic Table'!A12 -> CaO | B40: =B19 -> 29.63 | D40: ='Periodic Table'!C12 -> Ca | E40: =G19 -> 2.5438022
H41: X(Fe)
D42: tot. cat. | E42: =G21 -> 8 | G42: FeT/FeT+Mg | H42: =(E36+E37)/(E36+E37+E39) -> 0.87505003
A43: total | B43: =SUM(B32:B40) -> 100.11847 | D43: tot. oxy. | E43: =H21 -> 12 | G43: Fe2/Fe2+Mg | H43: =(E37)/(E37+E39) -> 0.59715855
A46: Site Occupancies & End Members | E46: end | F46: mol % | G46: mol % | H46: mol %
B47: cubic | C47: octahedral | D47: tetrahedral | E47: member | F47: with | G47: cation ratio | H47: cation ratio
B48: 8-fold | C48: 6-fold | D48: 4-fold | F48: Fe3+, etc. | G48: total Fe | H48: Fe2+
...

Sheet Olivine
A1: Recalculation of an olivine anlaysis (all Fe as FeO) and solving for Fe+3
A3: Sample calculation below is shown for an olivine from a lherzolite.
A4: Replace numbers in red with your analysis to normalize your sample.
A5: Do not include a value for Fe2O3 (in blue) unless it was determined by analysis.
A6: If you omit a value for Fe2O3, it will be calculated, if possible, from charge balance.
A8: Analysis
B9: analysis | C9: mole | D9: mole | E9: norm. | F9: norm. | G9: atom | H9: norm
A10: oxide | B10: wt % | C10: cations | D10: oxygen | E10: cations | F10: oxygen | G10: units | H10: oxygen
A11: ='Periodic Table'!A4 -> SiO2 | B11: 38.48 | C11: ='Periodic Table'!D4*B11/'Periodic Table'!B4 -> 0.64043352 | D11: ='Periodic Table'!E4*B11/'Periodic Table'!B4 -> 1.280867 | E11: =IF(B$15>0,H$22*C11/D$21,G$22*C11/C$21) -> 0.98838392 | F11: =E11*'Periodic Table'!E4/'Periodic Table'!D4 -> 1.9767678 | G11: =E11 -> 0.98838392 | H11: =F11 -> 1.9767678
A12: ='Periodic Table'!A5 -> TiO2 | B12: 0.01 | C12: ='Periodic Table'!D5*B12/'Periodic Table'!B5 -> 0.00012515833 | D12: ='Periodic Table'!E5*B12/'Periodic Table'!B5 -> 0.00025031665 | E12: =IF(B$15>0,H$22*C12/D$21,G$22*C12/C$21) -> 0.0001931574 | F12: =E12*'Periodic Table'!E5/'Periodic Table'!D5 -> 0.00038631481 | G12: =E12 -> 0.0001931574 | H12: =F12 -> 0.00038631481
A13: ='Periodic Table'!A6 -> Al2O3 | B13: 0.13 | C13: ='Periodic Table'!D6*B13/'Periodic Table'!B6 -> 0.0025499876 | D13: ='Periodic Table'!E6*B13/'Periodic Table'!B6 -> 0.0038249814 | E13: =IF(B$15>0,H$22*C13/D$21,G$22*C13/C$21) -> 0.0039354073 | F13: =E13*'Periodic Table'!E6/'Periodic Table'!D6 -> 0.0059031109 | G13: =E13 -> 0.0039354073 | H13: =F13 -> 0.0059031109
A14: ='Periodic Table'!A8 -> Cr2O3 | B14: 0 | C14: ='Periodic Table'!D8*B14/'Periodic Table'!B8 -> 0 | D14: ='Periodic Table'!E8*B14/'Periodic Table'!B8 -> 0 | E14: =IF(B$15>0,H$22*C14/D$21,G$22*C14/C$21) -> 0 | F14: =E14*'Periodic Table'!E8/'Periodic Table'!D8 -> 0 | G14: =E14 -> 0 | H14: =F14 -> 0
A15: ='Periodic Table'!A7 -> Fe2O3 | B15: 0 | C15: =IF(B15>0,'Periodic Table'!D7*B15/'Periodic Table'!B7,0) -> 0 | D15: =IF(B15>0,'Periodic Table'!E7*B15/'Periodic Table'!B7,0) -> 0 | E15: =IF(B$15>0,H$22*C15/D$21,G$22*C15/C$21) -> 0 | F15: =E15*'Periodic Table'!E7/'Periodic Table'!D7 -> 0 | G15: =IF(B15>0,E15,IF((2*H22)-E24>0,(2*H22)-E24,0)) -> 0.018910428 | H15: ='Periodic Table'!E7*G15/'Periodic Table'!D7 -> 0.028365642
A16: ='Periodic Table'!A9 -> FeO | B16: 20.99 | C16: ='Periodic Table'!D9*B16/'Periodic Table'!B9 -> 0.29215103 | D16: ='Periodic Table'!E9*B16/'Periodic Table'!B9 -> 0.29215103 | E16: =IF(B$15>0,H$22*C16/D$21,G$22*C16/C$21) -> 0.450878 | F16: =E16*'Periodic Table'!E9/'Periodic Table'!D9 -> 0.450878 | G16: =IF(B15>0,E16,E16-G15) -> 0.43196757 | H16: ='Periodic Table'!E9*G16/'Periodic Table'!D9 -> 0.43196757
A17: ='Periodic Table'!A10 -> MnO | B17: 0.33 | C17: ='Periodic Table'!D10*B17/'Periodic Table'!B10 -> 0.0046519889 | D17: ='Periodic Table'!E10*B17/'Periodic Table'!B10 -> 0.0046519889 | E17: =IF(B$15>0,H$22*C17/D$21,G$22*C17/C$21) -> 0.0071794354 | F17: =E17*'Periodic Table'!E10/'Periodic Table'!D10 -> 0.0071794354 | G17: =E17 -> 0.0071794354 | H17: =F17 -> 0.0071794354
A18: ='Periodic Table'!A11 -> MgO | B18: 40.45 | C18: ='Periodic Table'!D11*B18/'Periodic Table'!B11 -> 1.0036125 | D18: ='Periodic Table'!E11*B18/'Periodic Table'!B11 -> 1.0036125 | E18: =IF(B$15>0,H$22*C18/D$21,G$22*C18/C$21) -> 1.5488797 | F18: =E18*'Periodic Table'!E11/'Periodic Table'!D11 -> 1.5488797 | G18: =E18 -> 1.5488797 | H18: =F18 -> 1.5488797
A19: ='Periodic Table'!A12 -> CaO | B19: 0.02 | C19: ='Periodic Table'!D12*B19/'Periodic Table'!B12 -> 0.0003566372 | D19: ='Periodic Table'!E12*B19/'Periodic Table'!B12 -> 0.0003566372 | E19: =IF(B$15>0,H$22*C19/D$21,G$22*C19/C$21) -> 0.00055039978 | F19: =E19*'Periodic Table'!E12/'Periodic Table'!D12 -> 0.00055039978 | G19: =E19 -> 0.00055039978 | H19: =F19 -> 0.00055039978
A21: total | B21: =SUM(B11:B19) -> 100.41 | C21: =SUM(C11:C19) -> 1.9438808 | D21: =SUM(D11:D19) -> 2.5857145 | E21: =SUM(E11:E19) -> 3 | F21: =SUM(F11:F19) -> 3.9905448 | G21: =SUM(G11:G19) -> 3 | H21: =SUM(H11:H19) -> 4
A22: ideal | G22: 3 | H22: 4
E23: =IF(G24<7.985,"Note: insufficient cation charge",IF(G24>8.015,"Note: too much cation charge"," "))
A24: calculated charge | C24: =4*(C11+C12)+3*(C13+C15+C14)+2*(C16+C17+C18+C19) -> 5.171429 | D24: =2*SUM(D11:D19)*(-1) -> -5.171429 | E24: =4*(E11+E12)+3*(E13+E15+E14)+2*(E16+E17+E18+E19) -> 7.9810896 | F24: =2*SUM(F11:F19)*(-1) -> -7.9810896 | G24: =4*(G11+G12)+3*(G13+G15+G14)+2*(G16+G17+G18+G19) -> 8 | H24: =2*SUM(H11:H19)*(-1) -> -8
A26: Results of normalization are given in the box, below. If some Fe was calculated to
A27: be Fe3+, the total for the analysis will inrease.
A28: End member %s are based on Mn (Te), Mg (Fo), Fe-total (Fa), and Ca ratios only.
A30: Normalized Analysis
G31: end | H31: mole
A32: oxide | B32: wt % | D32: cations | E32: atoms | G32: member | H32: %*
A33: ='Periodic Table'!A4 -> SiO2 | B33: =B11 -> 38.48 | D33: ='Periodic Table'!C4 -> Si | E33: =G11 -> 0.98838392 | G33: Te | H33: =100*E39/(E$39+E$40+E$38+E$37+E$41) -> 0.35763288
A34: ='Periodic Table'!A5 -> TiO2 | B34: =B12 -> 0.01 | D34: ='Periodic Table'!C5 -> Ti | E34: =G12 -> 0.0001931574 | G34: Fo | H34: =100*E40/(E$39+E$40+E$38+E$37+E$41) -> 77.155134
A35: ='Periodic Table'!A6 -> Al2O3 | B35: =B13 -> 0.13 | D35: ='Periodic Table'!C6 -> Al | E35: =G13 -> 0.0039354073 | G35: Fa | H35: =100*(E38+E37)/(E$39+E$40+E$38+E$37+E$41) -> 22.459816
A36: ='Periodic Table'!A8 -> Cr2O3 | B36: =B14 -> 0 | D36: ='Periodic Table'!C8 -> Cr | E36: =G14 -> 0 | G36: Ca-Ol | H36: =100*E41/(E$39+E$40+E$38+E$37+E$41) -> 0.027417345
A37: ='Periodic Table'!A7 -> Fe2O3 | B37: =IF(B15>0,B15,('Periodic Table'!B7/(2*'Periodic Table'!B9))*B16*G15/(G15+G16)) -> 0.97837073 | D37: ='Periodic Table'!C7 -> Fe3 | E37: =G15 -> 0.018910428
A38: ='Periodic Table'!A9 -> FeO | B38: =IF(B15>0,B16,B16*G16/(G16+G15)) -> 20.109651 | D38: ='Periodic Table'!C9 -> Fe2 | E38: =G16 -> 0.43196757 | G38: sum | H38: =SUM(H33:H36) -> 100
A39: ='Periodic Table'!A10 -> MnO | B39: =B17 -> 0.33 | D39: ='Periodic Table'!C10 -> Mn | E39: =G17 -> 0.0071794354
A40: ='Periodic Table'!A11 -> MgO | B40: =B18 -> 40.45 | D40: ='Periodic Table'!C11 -> Mg | E40: =G18 -> 1.5488797
A41: ='Periodic Table'!A12 -> CaO | B41: =B19 -> 0.02 | D41: ='Periodic Table'!C12 -> Ca | E41: =G19 -> 0.00055039978
D42: tot. cat. | E42: =G21 -> 3 | F42: =IF(E33<0.985,"Note: Si difficiency",IF(E33>1.015,"Note: Si excess"," "))
A43: total | B43: =SUM(B33:B41) -> 100.50802 | D43: tot. oxy. | E43: =H21 -> 4

Sheet Spinel
A1: Recalculation of a spinel anlaysis (all Fe as FeO) and solving for Fe+3
A3: Sample calculation below is shown for a spinel from the Adirondacks.
A4: Replace numbers in red with your analysis to normalize your sample.
A5: Do not include a value for Fe2O3 (in blue) unless it was determined by analysis.
A6: If you omit a value for Fe2O3, it will be calculated, if possible, from charge balance.
A8: Analysis
B9: analysis | C9: mole | D9: mole | E9: norm. | F9: norm. | G9: atom | H9: norm
A10: oxide | B10: wt % | C10: cations | D10: oxygen | E10: cations | F10: oxygen | G10: units | H10: oxygen
A11: ='Periodic Table'!A4 -> SiO2 | B11: 0 | C11: ='Periodic Table'!D4*B11/'Periodic Table'!B4 -> 0 | D11: ='Periodic Table'!E4*B11/'Periodic Table'!B4 -> 0 | E11: =IF(B$15>0,H$21*C11/D$20,G$21*C11/C$20) -> 0 | F11: =E11*'Periodic Table'!E4/'Periodic Table'!D4 -> 0 | G11: =E11 -> 0 | H11: =F11 -> 0
A12: ='Periodic Table'!A5 -> TiO2 | B12: 0.13 | C12: ='Periodic Table'!D5*B12/'Periodic Table'!B5 -> 0.0016270582 | D12: ='Periodic Table'!E5*B12/'Periodic Table'!B5 -> 0.0032541165 | E12: =IF(B$15>0,H$21*C12/D$20,G$21*C12/C$20) -> 0.0024365198 | F12: =E12*'Periodic Table'!E5/'Periodic Table'!D5 -> 0.0048730395 | G12: =E12 -> 0.0024365198 | H12: =F12 -> 0.0048730395
A13: ='Periodic Table'!A6 -> Al2O3 | B13: 65.4 | C13: ='Periodic Table'!D6*B13/'Periodic Table'!B6 -> 1.2828399 | D13: ='Periodic Table'!E6*B13/'Periodic Table'!B6 -> 1.9242599 | E13: =IF(B$15>0,H$21*C13/D$20,G$21*C13/C$20) -> 1.9210528 | F13: =E13*'Periodic Table'!E6/'Periodic Table'!D6 -> 2.8815792 | G13: =E13 -> 1.9210528 | H13: =F13 -> 2.8815792
A14: ='Periodic Table'!A8 -> Cr2O3 | B14: 0 | C14: ='Periodic Table'!D8*B14/'Periodic Table'!B8 -> 0 | D14: ='Periodic Table'!E8*B14/'Periodic Table'!B8 -> 0 | E14: =IF(B$15>0,H$21*C14/D$20,G$21*C14/C$20) -> 0 | F14: =E14*'Periodic Table'!E8/'Periodic Table'!D8 -> 0 | G14: =E14 -> 0 | H14: =F14 -> 0
A15: ='Periodic Table'!A7 -> Fe2O3 | B15: 0 | C15: =IF(B15>0,'Periodic Table'!D7*B15/'Periodic Table'!B7,0) -> 0 | D15: =IF(B15>0,'Periodic Table'!E7*B15/'Periodic Table'!B7,0) -> 0 | E15: =IF(B$15>0,H$21*C15/D$20,G$21*C15/C$20) -> 0 | F15: =E15*'Periodic Table'!E7/'Periodic Table'!D7 -> 0 | G15: =IF(B15>0,E15,IF((2*H21)-E23>0,(2*H21)-E23,0)) -> 0.074074137 | H15: ='Periodic Table'!E7*G15/'Periodic Table'!D7 -> 0.11111121
A16: ='Periodic Table'!A9 -> FeO | B16: 11.92 | C16: ='Periodic Table'!D9*B16/'Periodic Table'!B9 -> 0.1659095 | D16: ='Periodic Table'!E9*B16/'Periodic Table'!B9 -> 0.1659095 | E16: =IF(B$15>0,H$21*C16/D$20,G$21*C16/C$20) -> 0.24844948 | F16: =E16*'Periodic Table'!E9/'Periodic Table'!D9 -> 0.24844948 | G16: =IF(B15>0,E16,E16-G15) -> 0.17437534 | H16: ='Periodic Table'!E9*G16/'Periodic Table'!D9 -> 0.17437534
A17: ='Periodic Table'!A10 -> MnO | B17: 0.1 | C17: ='Periodic Table'!D10*B17/'Periodic Table'!B10 -> 0.0014096936 | D17: ='Periodic Table'!E10*B17/'Periodic Table'!B10 -> 0.0014096936 | E17: =IF(B$15>0,H$21*C17/D$20,G$21*C17/C$20) -> 0.0021110162 | F17: =E17*'Periodic Table'!E10/'Periodic Table'!D10 -> 0.0021110162 | G17: =E17 -> 0.0021110162 | H17: =F17 -> 0.0021110162
A18: ='Periodic Table'!A11 -> MgO | B18: 22.23 | C18: ='Periodic Table'!D11*B18/'Periodic Table'!B11 -> 0.55155268 | D18: ='Periodic Table'!E11*B18/'Periodic Table'!B11 -> 0.55155268 | E18: =IF(B$15>0,H$21*C18/D$20,G$21*C18/C$20) -> 0.82595016 | F18: =E18*'Periodic Table'!E11/'Periodic Table'!D11 -> 0.82595016 | G18: =E18 -> 0.82595016 | H18: =F18 -> 0.82595016
A20: total | B20: =SUM(B11:B18) -> 99.78 | C20: =SUM(C11:C18) -> 2.0033388 | D20: =SUM(D11:D18) -> 2.6463859 | E20: =SUM(E11:E18) -> 3 | F20: =SUM(F11:F18) -> 3.9629629 | G20: =SUM(G11:G18) -> 3 | H20: =SUM(H11:H18) -> 4
A21: desired | G21: 3 | H21: 4
E22: =IF(G23<7.985,"Note: insufficient cation charge",IF(G23>8.015,"Note: too much cation charge"," "))
A23: calculated charge | C23: =4*(C11+C12)+3*(C13+C15+C14)+2*(C16+C17+C18) -> 5.2927717 | D23: =2*SUM(D11:D18)*-1 -> -5.2927717 | E23: =4*(E11+E12)+3*(E13+E15+E14)+2*(E16+E17+E18) -> 7.9259259 | F23: =2*SUM(F11:F18)*-1 -> -7.9259259 | G23: =4*(G11+G12)+3*(G13+G15+G14)+2*(G16+G17+G18) -> 8 | H23: =2*SUM(H11:H18)*-1 -> -8
A25: Results of normalization are given in the box, below. Because some Fe was calculated to
A26: be Fe3+, the total for the analysis increased.
A28: Normalized Analysis
A30: oxide | B30: wt % | D30: cations | E30: atoms
A31: ='Periodic Table'!A4 -> SiO2 | B31: =B11 -> 0 | D31: ='Periodic Table'!C4 -> Si | E31: =G11 -> 0
A32: ='Periodic Table'!A5 -> TiO2 | B32: =B12 -> 0.13 | D32: ='Periodic Table'!C5 -> Ti | E32: =G12 -> 0.0024365198
A33: ='Periodic Table'!A6 -> Al2O3 | B33: =B13 -> 65.4 | D33: ='Periodic Table'!C6 -> Al | E33: =G13 -> 1.9210528
A34: ='Periodic Table'!A8 -> Cr2O3 | B34: =B14 -> 0 | D34: ='Periodic Table'!C8 -> Cr | E34: =G14 -> 0
A35: ='Periodic Table'!A7 -> Fe2O3 | B35: =('Periodic Table'!$D$6*$B$33/($E$33*'Periodic Table'!$B$6))*'Periodic Table'!$B7*$E35/'Periodic Table'!$D7 -> 3.9496032 | D35: ='Periodic Table'!C7 -> Fe3 | E35: =G15 -> 0.074074137
A36: ='Periodic Table'!A9 -> FeO | B36: =('Periodic Table'!$D$6*$B$33/($E$33*'Periodic Table'!$B$6))*'Periodic Table'!$B9*$E36/'Periodic Table'!$D9 -> 8.3661035 | D36: ='Periodic Table'!C9 -> Fe2 | E36: =G16 -> 0.17437534
A37: ='Periodic Table'!A10 -> MnO | B37: =B17 -> 0.1 | D37: ='Periodic Table'!C10 -> Mn | E37: =G17 -> 0.0021110162
A38: ='Periodic Table'!A11 -> MgO | B38: =B18 -> 22.23 | D38: ='Periodic Table'!C11 -> Mg | E38: =G18 -> 0.82595016
D39: tot. cat. | E39: =G20 -> 3
A40: total | B40: =SUM(B31:B38) -> 100.17571 | D40: tot. oxy. | E40: =H20 -> 4

Sheet Periodic Table
A3: oxide | B3: MolWt | C3: cation | D3: #cations | E3: #oxygen | F3: cation wt
A4: SiO2 | B4: =28.0855+2*15.9994 -> 60.0843 | C4: Si | D4: 1 | E4: 2 | F4: 28.0855
A5: TiO2 | B5: =47.9+2*15.9994 -> 79.8988 | C5: Ti | D5: 1 | E5: 2 | F5: 47.9
A6: Al2O3 | B6: =2*26.98154+3*15.9994 -> 101.96128 | C6: Al | D6: 2 | E6: 3 | F6: 26.98154
A7: Fe2O3 | B7: =2*55.847+3*15.9994 -> 159.6922 | C7: Fe3 | D7: 2 | E7: 3 | F7: 55.847
A8: Cr2O3 | B8: =2*51.996+3*15.9994 -> 151.9902 | C8: Cr | D8: 2 | E8: 3 | F8: 51.996
A9: FeO | B9: =55.847+15.9994 -> 71.8464 | C9: Fe2 | D9: 1 | E9: 1 | F9: 55.847
A10: MnO | B10: =54.938+15.9994 -> 70.9374 | C10: Mn | D10: 1 | E10: 1 | F10: 54.938
A11: MgO | B11: =24.305+15.9994 -> 40.3044 | C11: Mg | D11: 1 | E11: 1 | F11: 24.305
A12: CaO | B12: =40.08+15.9994 -> 56.0794 | C12: Ca | D12: 1 | E12: 1 | F12: 40.08
A13: BaO | B13: 153.3294 | C13: Ba | D13: 1 | E13: 1 | F13: 137.77
A14: Na2O | B14: =2*22.98977+15.9994 -> 61.97894 | C14: Na | D14: 2 | E14: 1 | F14: 22.98977
A15: K2O | B15: =2*39.0983+15.9994 -> 94.196 | C15: K | D15: 2 | E15: 1 | F15: 39.0983
